
C:\Users\79247\Desktop\Theo\python_projects\remote_file_access
(rfa_env) λ python app.py run
成功設定資料庫連線: default
成功設定資料庫連線: log_db
成功註冊藍圖: view.aaa.bp
成功註冊藍圖: view.userCtrl.userctrl
伺服器將在 http://0.0.0.0:5000 上啟動
 * Serving Flask app 'app'
 * Debug mode: on
WARNING: This is a development server. Do not use it in a production deployment. Use a production WSGI server instead.
 * Running on all addresses (0.0.0.0)
 * Running on http://127.0.0.1:5000
 * Running on http://192.168.18.16:5000
Press CTRL+C to quit
 * Restarting with watchdog (windowsapi)
成功設定資料庫連線: default
成功設定資料庫連線: log_db
成功註冊藍圖: view.aaa.bp
成功註冊藍圖: view.userCtrl.userctrl
伺服器將在 http://0.0.0.0:5000 上啟動
 * Debugger is active!
 * Debugger PIN: 604-488-867
127.0.0.1 - - [24/Aug/2025 16:35:41] "POST /userCtrl/createUser HTTP/1.1" 500 -
Traceback (most recent call last):
  File "C:\Users\79247\Desktop\Theo\python_projects\remote_file_access\rfa_env\Lib\site-packages\flask\app.py", line 1536, in __call__
    return self.wsgi_app(environ, start_response)
           ~~~~~~~~~~~~~^^^^^^^^^^^^^^^^^^^^^^^^^
  File "C:\Users\79247\Desktop\Theo\python_projects\remote_file_access\rfa_env\Lib\site-packages\flask\app.py", line 1514, in wsgi_app
    response = self.handle_exception(e)
  File "C:\Users\79247\Desktop\Theo\python_projects\remote_file_access\rfa_env\Lib\site-packages\flask\app.py", line 1511, in wsgi_app
    response = self.full_dispatch_request()
  File "C:\Users\79247\Desktop\Theo\python_projects\remote_file_access\rfa_env\Lib\site-packages\flask\app.py", line 919, in full_dispatch_request
    rv = self.handle_user_exception(e)
  File "C:\Users\79247\Desktop\Theo\python_projects\remote_file_access\rfa_env\Lib\site-packages\flask\app.py", line 917, in full_dispatch_request
    rv = self.dispatch_request()
  File "C:\Users\79247\Desktop\Theo\python_projects\remote_file_access\rfa_env\Lib\site-packages\flask\app.py", line 902, in dispatch_request
    return self.ensure_sync(self.view_functions[rule.endpoint])(**view_args)  # type: ignore[no-any-return]
           ~~~~~~~~~~~~~~~~~~~~~~~~~~~~~~~~~~~~~~~~~~~~~~~~~~~~^^^^^^^^^^^^^
  File "C:\Users\79247\Desktop\Theo\python_projects\remote_file_access\rfa_env\Lib\site-packages\flask_openapi3\scaffold.py", line 123, in view_func
    response = func(**func_kwargs)
  File "C:\Users\79247\Desktop\Theo\python_projects\remote_file_access\view\userCtrl.py", line 28, in create_user
    Outcome_dict = data.data()
  File "C:\Users\79247\Desktop\Theo\python_projects\remote_file_access\controller\Cont_userCtrl.py", line 30, in data
    q_get_roles_id = self.session.execute(get_roles_id).all()
  File "C:\Users\79247\Desktop\Theo\python_projects\remote_file_access\rfa_env\Lib\site-packages\sqlalchemy\engine\result.py", line 1384, in all
    return self._allrows()
           ~~~~~~~~~~~~~^^
  File "C:\Users\79247\Desktop\Theo\python_projects\remote_file_access\rfa_env\Lib\site-packages\sqlalchemy\engine\result.py", line 548, in _allrows
    rows = self._fetchall_impl()
  File "C:\Users\79247\Desktop\Theo\python_projects\remote_file_access\rfa_env\Lib\site-packages\sqlalchemy\engine\result.py", line 2275, in _fetchall_impl
    return list(self.iterator)
  File "C:\Users\79247\Desktop\Theo\python_projects\remote_file_access\rfa_env\Lib\site-packages\sqlalchemy\orm\loading.py", line 220, in chunks
    fetch = cursor._raw_all_rows()
  File "C:\Users\79247\Desktop\Theo\python_projects\remote_file_access\rfa_env\Lib\site-packages\sqlalchemy\engine\result.py", line 541, in _raw_all_rows
    return [make_row(row) for row in rows]
            ~~~~~~~~^^^^^
  File "lib/sqlalchemy/cyextension/resultproxy.pyx", line 22, in sqlalchemy.cyextension.resultproxy.BaseRow.__init__
  File "lib/sqlalchemy/cyextension/resultproxy.pyx", line 79, in sqlalchemy.cyextension.resultproxy._apply_processors
  File "lib/sqlalchemy/cyextension/processors.pyx", line 40, in sqlalchemy.cyextension.processors.str_to_datetime
TypeError: fromisoformat: argument must be str